Workbook

Sheet dataset_info
A1: patient_id | B1: dataset | C1: bilateral_breast_cancer | D1: multifocal_cancer | E1: nac_agent | F1: endocrine_therapy | G1: anti_her2_neu_therapy | H1: pcr | I1: mastectomy_post_nac | J1: days_to_follow_up | K1: days_to_recurrence | L1: days_to_metastasis | M1: days_to_death | N1: hr | O1: er | P1: pr | Q1: her2 | R1: mammaprint | S1: oncotype_score | T1: nottingham_grade | U1: tumor_subtype | V1: age | W1: menopause | X1: ethnicity | Y1: has_implant | Z1: weight | AA1: patient_size | AB1: bmi_group | AC1: breast_density | AD1: view | AE1: bilateral_mri | AF1: num_phases | AG1: fat_suppressed | AH1: field_strength | AI1: image_rows | AJ1: image_columns | AK1: num_slices | AL1: pixel_spacing | AM1: slice_thickness | AN1: site | AO1: manufacturer | AP1: scanner_model | AQ1: high_bit | AR1: window_center | AS1: window_width | AT1: echo_time | AU1: repetition_time | AV1: acquisition_times | AW1: acquisition_date | AX1: tcia_series_uid
A2: DUKE_001 | B2: DUKE | C2: 0 | D2: 0 | F2: 0 | G2: 1 | H2: 0 | I2: 0 | J2: 2940 | K2: 0 | M2: 0 | N2: 0 | O2: 0 | P2: 0 | Q2: 1 | T2: intermediate | U2: her2_pure | V2: 41 | W2: pre | X2: african american | Y2: 0 | Z2: 90.264893 | AA2: 1.6002032 | AB2: obesity_class_2 | AD2: axial | AE2: 1 | AF2: 5 | AG2: 1 | AH2: 1.5 | AI2: 448 | AJ2: 448 | AK2: 160 | AL2: [0.80357140302658, 0.80357140302658] | AM2: 1.1 | AN2: DUKE | AO2: SIEMENS | AP2: Avanto | AQ2: 11 | AR2: 53 | AS2: 145 | AT2: 1.36 | AU2: 4.12 | AV2: [0, 584, 714, 846, 977] | AX2: 1.3.6.1.4.1.14519.5.2.1.185777849803665244536713316058283493877
A3: DUKE_002 | B3: DUKE | C3: 0 | D3: 0 | F3: 0 | G3: 0 | H3: 0 | I3: 0 | J3: 1649 | K3: 0 | M3: 0 | N3: 0 | O3: 0 | P3: 0 | Q3: 0 | T3: high | U3: triple_negative | V3: 38 | W3: pre | X3: african american | Y3: 0 | AD3: axial | AE3: 1 | AF3: 4 | AG3: 1 | AH3: 3 | AI3: 512 | AJ3: 512 | AK3: 142 | AL3: [0.5859, 0.5859] | AM3: 1.3 | AN3: DUKE | AO3: GE | AP3: Signa HDxt | AQ3: 15 | AR3: 326 | AS3: 652 | AT3: 2.704 | AU3: 6.918 | AV3: [0, 165, 288, 411] | AX3: 1.3.6.1.4.1.14519.5.2.1.292087950444413314643924739363083325442
A4: DUKE_005 | B4: DUKE | C4: 0 | D4: 1 | F4: 0 | G4: 1 | H4: 1 | I4: 1 | J4: 1845 | K4: 0 | M4: 0 | N4: 1 | O4: 1 | P4: 0 | Q4: 1 | T4: high | U4: her2_enriched | V4: 38 | W4: pre | X4: hispanic | Y4: 0 | Z4: 54.431091 | AA4: 1.6256033 | AB4: normal | AD4: axial | AE4: 1 | AF4: 4 | AG4: 1 | AH4: 1.5 | AI4: 448 | AJ4: 448 | AK4: 160 | AL4: [0.78125, 0.78125] | AM4: 1 | AN4: DUKE | AO4: SIEMENS | AP4: Avanto | AQ4: 11 | AR4: 106 | AS4: 288 | AT4: 1.34 | AU4: 4.27 | AV4: [0, 183, 289, 398] | AX4: 1.3.6.1.4.1.14519.5.2.1.308267282790822635275517329397281651993
A5: DUKE_009 | B5: DUKE | C5: 0 | D5: 1 | F5: 0 | G5: 0 | H5: 1 | I5: 0 | J5: 1554 | K5: 0 | M5: 0 | N5: 0 | O5: 0 | P5: 0 | Q5: 0 | T5: high | U5: triple_negative | V5: 56 | W5: post | X5: caucasian | Y5: 0 | AD5: axial | AE5: 1 | AF5: 4 | AG5: 1 | AH5: 3 | AI5: 512 | AJ5: 512 | AK5: 156 | AL5: [0.6641, 0.6641] | AM5: 1.1 | AN5: DUKE | AO5: GE | AP5: Signa HDxt | AQ5: 15 | AR5: 231 | AS5: 462 | AT5: 2.604 | AU5: 6.032 | AV5: [0, 199, 314, 429] | AX5: 1.3.6.1.4.1.14519.5.2.1.195599593590134921565234265546312466184
A6: DUKE_010 | B6: DUKE | C6: 0 | D6: 1 | F6: 0 | G6: 0 | H6: 0 | I6: 1 | J6: 384 | K6: 407 | M6: 471 | N6: 0 | O6: 0 | P6: 0 | Q6: 0 | T6: high | U6: triple_negative | V6: 67 | W6: post | X6: caucasian | Y6: 0 | AD6: axial | AE6: 1 | AF6: 4 | AG6: 1 | AH6: 3 | AI6: 512 | AJ6: 512 | AK6: 146 | AL6: [0.6641, 0.6641] | AM6: 1 | AN6: DUKE | AO6: GE | AP6: Signa HDxt | AQ6: 15 | AR6: 532 | AS6: 1064 | AT6: 2.436 | AU6: 5.668 | AV6: [0, 156, 255, 355] | AX6: 1.3.6.1.4.1.14519.5.2.1.139066171032552599962813047852732821046
A7: DUKE_012 | B7: DUKE | C7: 0 | D7: 1 | F7: 0 | G7: 0 | H7: 0 | I7: 1 | J7: 256 | K7: 319 | M7: 414 | N7: 0 | O7: 0 | P7: 0 | Q7: 0 | T7: high | U7: triple_negative | V7: 43 | W7: pre | X7: african american | Y7: 0 | AD7: axial | AE7: 1 | AF7: 4 | AG7: 1 | AH7: 1.5 | AI7: 512 | AJ7: 512 | AK7: 178 | AL7: [0.7422, 0.7422] | AM7: 1.2 | AN7: DUKE | AO7: GE | AP7: Optima MR450w | AQ7: 15 | AR7: 339 | AS7: 678 | AT7: 2.436 | AU7: 5.208 | AV7: [0, 185, 305, 425] | AX7: 1.3.6.1.4.1.14519.5.2.1.29690579104517430202999923277168936221
A8: DUKE_019 | B8: DUKE | C8: 0 | D8: 1 | F8: 0 | G8: 0 | H8: 0 | I8: 1 | J8: 2183 | K8: 0 | M8: 0 | N8: 1 | O8: 1 | P8: 1 | Q8: 0 | T8: intermediate | U8: luminal | V8: 35 | W8: pre | X8: caucasian | Y8: 0 | Z8: 70.306826 | AA8: 1.6764034 | AB8: overweight | AD8: axial | AE8: 1 | AF8: 4 | AG8: 1 | AH8: 1.5 | AI8: 320 | AJ8: 320 | AK8: 160 | AL8: [1.0625, 1.0625] | AM8: 1.1 | AN8: DUKE | AO8: SIEMENS | AP8: Avanto | AQ8: 11 | AR8: 47 | AS8: 128 | AT8: 1.5 | AU8: 4.26 | AV8: [0, 277, 395, 512] | AX8: 1.3.6.1.4.1.14519.5.2.1.29840080323274044917609393923117431278
A9: DUKE_021 | B9: DUKE | C9: 0 | D9: 1 | F9: 0 | G9: 0 | H9: 0 | I9: 1 | J9: 1416 | K9: 0 | M9: 0 | N9: 1 | O9: 1 | P9: 1 | Q9: 0 | T9: intermediate | U9: luminal | V9: 43 | W9: post | X9: caucasian | Y9: 0 | Z9: 97.52 | AB9: obesity_class_2 | AD9: axial | AE9: 1 | AF9: 4 | AG9: 1 | AH9: 1.5 | AI9: 512 | AJ9: 512 | AK9: 176 | AL9: [0.7422, 0.7422] | AM9: 1 | AN9: DUKE | AO9: GE | AP9: Optima MR450w | AQ9: 15 | AR9: 390 | AS9: 780 | AT9: 2.436 | AU9: 5.284 | AV9: [0, 176, 291, 406] | AX9: 1.3.6.1.4.1.14519.5.2.1.284279810676391467352803707565165173046
A10: DUKE_022 | B10: DUKE | C10: 0 | D10: 1 | F10: 0 | G10: 1 | H10: 0 | I10: 0 | J10: 2014 | K10: 0 | M10: 0 | N10: 1 | O10: 1 | P10: 1 | Q10: 1 | U10: her2_enriched | V10: 53 | W10: post | X10: caucasian | Y10: 0 | Z10: 76.65712 | AB10: overweight | AC10: c | AD10: axial | AE10: 1 | AF10: 5 | AG10: 1 | AH10: 1.5 | AI10: 448 | AJ10: 448 | AK10: 160 | AL10: [0.73660713434219, 0.73660713434219] | AM10: 1.1 | AN10: DUKE | AO10: SIEMENS | AP10: Avanto | AQ10: 11 | AR10: 46 | AS10: 123 | AT10: 1.4 | AU10: 4.14 | AV10: [0, 762, 892, 1018, 1147] | AX10: 1.3.6.1.4.1.14519.5.2.1.69670824244476046203828147718377984832
A11: DUKE_028 | B11: DUKE | C11: 0 | D11: 0 | F11: 0 | G11: 0 | H11: 0 | I11: 1 | J11: 162 | K11: 197 | M11: 0 | N11: 0 | O11: 0 | P11: 0 | Q11: 0 | T11: high | U11: triple_negative | V11: 41 | W11: pre | X11: caucasian | Y11: 0 | AD11: axial | AE11: 1 | AF11: 4 | AG11: 1 | AH11: 3 | AI11: 448 | AJ11: 448 | AK11: 208 | AL11: [0.78125, 0.78125] | AM11: 1 | AN11: DUKE | AO11: SIEMENS | AP11: Skyra | AQ11: 15 | AR11: 47 | AS11: 134 | AT11: 1.44 | AU11: 3.77 | AV11: [0, 190, 289, 388] | AX11: 1.3.6.1.4.1.14519.5.2.1.320596235836817677689318971087443086949
A12: DUKE_032 | B12: DUKE | C12: 0 | D12: 1 | F12: 0 | G12: 0 | H12: 0 | I12: 1 | J12: 1525 | K12: 0 | M12: 0 | N12: 1 | O12: 1 | P12: 1 | Q12: 0 | S12: 18 | U12: luminal | V12: 48 | W12: pre | X12: asian | Y12: 0 | Z12: 58.967 | AB12: normal | AC12: d | AD12: axial | AE12: 1 | AF12: 5 | AG12: 1 | AH12: 1.5 | AI12: 512 | AJ12: 512 | AK12: 178 | AL12: [0.6055, 0.6055] | AM12: 1 | AN12: DUKE | AO12: GE | AP12: SIGNA HDx | AQ12: 15 | AR12: 447 | AS12: 895 | AT12: 2.372 | AU12: 4.988 | AV12: [0, 255, 371, 487, 603] | AX12: 1.3.6.1.4.1.14519.5.2.1.142556628749506471715658430177460848775
A13: DUKE_034 | B13: DUKE | C13: 0 | D13: 0 | F13: 0 | G13: 0 | I13: 1 | J13: 1819 | K13: 0 | M13: 0 | N13: 1 | O13: 1 | P13: 1 | Q13: 0 | U13: luminal | V13: 48 | W13: pre | X13: caucasian | Y13: 0 | Z13: 83.915 | AB13: obesity_class_1 | AD13: axial | AE13: 1 | AF13: 5 | AG13: 1 | AH13: 3 | AI13: 512 | AJ13: 512 | AK13: 148 | AL13: [0.7031, 0.7031] | AM13: 1.2 | AN13: DUKE | AO13: GE | AP13: SIGNA HDx | AQ13: 15 | AR13: 1054 | AS13: 2109 | AT13: 2.388 | AU13: 5.174 | AV13: [0, 172, 265, 357, 450] | AX13: 1.3.6.1.4.1.14519.5.2.1.165419398503501068868667981377889644471
A14: DUKE_040 | B14: DUKE | C14: 0 | D14: 1 | F14: 0 | G14: 0 | H14: 0 | I14: 0 | J14: 1985 | K14: 0 | M14: 0 | N14: 1 | O14: 1 | P14: 1 | Q14: 0 | U14: luminal | V14: 48 | W14: pre | X14: african american | Y14: 0 | Z14: 99.790334 | AB14: obesity_class_2 | AD14: axial | AE14: 1 | AF14: 5 | AG14: 1 | AH14: 3 | AI14: 448 | AJ14: 448 | AK14: 160 | AL14: [0.75892859697342, 0.75892859697342] | AM14: 1.1 | AN14: DUKE | AO14: SIEMENS | AP14: TrioTim | AQ14: 11 | AR14: 54 | AS14: 174 | AT14: 1.36 | AU14: 3.54 | AV14: [0, 210, 327, 434, 539] | AX14: 1.3.6.1.4.1.14519.5.2.1.326715859685480256527395450683442312123
A15: DUKE_041 | B15: DUKE | C15: 0 | D15: 0 | F15: 0 | G15: 0 | H15: 0 | I15: 1 | J15: 2567 | K15: 0 | M15: 0 | N15: 1 | O15: 1 | P15: 1 | Q15: 0 | S15: 27 | T15: intermediate | U15: luminal | V15: 67 | W15: post | X15: caucasian | Y15: 0 | Z15: 68.039 | AB15: normal | AD15: axial | AE15: 1 | AF15: 5 | AG15: 1 | AH15: 3 | AI15: 512 | AJ15: 512 | AK15: 168 | AL15: [0.6836, 0.6836] | AM15: 1 | AN15: DUKE | AO15: GE | AP15: SIGNA HDx | AQ15: 15 | AR15: 513 | AS15: 1027 | AT15: 2.4 | AU15: 5.511 | AV15: [0, 314, 668, 778, 888] | AX15: 1.3.6.1.4.1.14519.5.2.1.236293724990342289056773559709687460093
A16: DUKE_043 | B16: DUKE | C16: 1 | D16: 0 | F16: 0 | G16: 0 | H16: 0 | I16: 0 | J16: 217 | K16: 260 | M16: 461 | N16: 0 | O16: 0 | P16: 0 | Q16: 0 | T16: intermediate | U16: triple_negative | V16: 46 | W16: pre | X16: caucasian | Y16: 0 | AD16: axial | AE16: 1 | AF16: 5 | AG16: 1 | AH16: 3 | AI16: 512 | AJ16: 512 | AK16: 188 | AL16: [0.6836, 0.6836] | AM16: 1 | AN16: DUKE | AO16: GE | AP16: SIGNA HDx | AQ16: 15 | AR16: 488 | AS16: 976 | AT16: 2.396 | AU16: 5.513 | AV16: [0, 648, 850, 982, 1118] | AX16: 1.3.6.1.4.1.14519.5.2.1.6793813290723618656258406154497169878
A17: DUKE_044 | B17: DUKE | C17: 0 | D17: 0 | F17: 0 | G17: 1 | H17: 1 | I17: 1 | J17: 2170 | K17: 0 | M17: 0 | N17: 0 | O17: 0 | P17: 0 | Q17: 1 | T17: high | U17: her2_pure | V17: 34 | W17: pre | X17: caucasian | Y17: 0 | Z17: 68.038864 | AA17: 1.6764034 | AB17: normal | AD17: axial | AE17: 1 | AF17: 5 | AG17: 1 | AH17: 1.5 | AI17: 448 | AJ17: 448 | AK17: 128 | AL17: [0.75892859697342, 0.75892859697342] | AM17: 1.1 | AN17: DUKE | AO17: SIEMENS | AP17: Avanto | AQ17: 11 | AR17: 133 | AS17: 288 | AT17: 1.39 | AU17: 4.12 | AV17: [0, 191, 291, 391, 491] | AX17: 1.3.6.1.4.1.14519.5.2.1.139830005215649431703224664916087614564
A18: DUKE_045 | B18: DUKE | C18: 0 | D18: 1 | F18: 0 | G18: 1 | H18: 1 | I18: 0 | J18: 1577 | K18: 0 | M18: 0 | N18: 1 | O18: 0 | P18: 1 | Q18: 1 | V18: 45 | W18: pre | X18: caucasian | Y18: 0 | Z18: 74.843 | AB18: overweight | AC18: c | AD18: axial | AE18: 1 | AF18: 4 | AG18: 1 | AH18: 1.5 | AI18: 512 | AJ18: 512 | AK18: 188 | AL18: [0.6641, 0.6641] | AM18: 1 | AN18: DUKE | AO18: GE | AP18: SIGNA HDx | AQ18: 15 | AR18: 381 | AS18: 762 | AT18: 2.32 | AU18: 4.936 | AV18: [0, 146, 261, 376] | AX18: 1.3.6.1.4.1.14519.5.2.1.301440525687899953712635567929052817508
A19: DUKE_046 | B19: DUKE | C19: 1 | D19: 0 | F19: 0 | G19: 0 | H19: 0 | I19: 1 | J19: 692 | K19: 0 | M19: 0 | N19: 1 | O19: 1 | P19: 1 | Q19: 0 | T19: high | U19: luminal | V19: 53 | W19: post | X19: african american | Y19: 0 | Z19: 77.110713 | AA19: 1.7272035 | AB19: overweight | AD19: axial | AE19: 1 | AF19: 4 | AG19: 1 | AH19: 3 | AI19: 448 | AJ19: 448 | AK19: 256 | AL19: [0.83705359697342, 0.83705359697342] | AM19: 1 | AN19: DUKE | AO19: SIEMENS | AP19: Skyra | AQ19: 11 | AR19: 51 | AS19: 146 | AT19: 1.44 | AU19: 3.77 | AV19: [0, 204, 334, 456] | AX19: 1.3.6.1.4.1.14519.5.2.1.35071805945810659801827406527930186176
A20: DUKE_048 | B20: DUKE | C20: 0 | D20: 0 | F20: 0 | G20: 0 | H20: 0 | I20: 1 | J20: 1603 | K20: 0 | M20: 0 | N20: 0 | O20: 0 | P20: 0 | Q20: 0 | T20: high | U20: triple_negative | V20: 40 | W20: pre | X20: caucasian | Y20: 0 | AD20: axial | AE20: 1 | AF20: 4 | AG20: 1 | AH20: 1.5 | AI20: 448 | AJ20: 448 | AK20: 176 | AL20: [0.75892859697342, 0.75892859697342] | AM20: 1 | AN20: DUKE | AO20: SIEMENS | AP20: Avanto | AQ20: 15 | AR20: 62 | AS20: 160 | AT20: 1.36 | AU20: 4.31 | AV20: [0, 177, 295, 411] | AX20: 1.3.6.1.4.1.14519.5.2.1.14969191741802921952501527627204705242
A21: DUKE_051 | B21: DUKE | C21: 0 | D21: 0 | F21: 0 | G21: 1 | H21: 0 | I21: 0 | J21: 1603 | K21: 0 | M21: 0 | N21: 1 | O21: 1 | P21: 1 | Q21: 1 | T21: high | U21: her2_enriched | V21: 38 | W21: pre | X21: caucasian | Y21: 0 | Z21: 73 | AB21: overweight | AD21: axial | AE21: 1 | AF21: 4 | AG21: 1 | AH21: 1.5 | AI21: 512 | AJ21: 512 | AK21: 200 | AL21: [0.7422, 0.7422] | AM21: 1 | AN21: DUKE | AO21: GE | AP21: Signa HDxt | AQ21: 15 | AR21: 251 | AS21: 503 | AT21: 2.232 | AU21: 4.812 | AV21: [0, 238, 356, 473] | AX21: 1.3.6.1.4.1.14519.5.2.1.56794322020151755238976088550992192797
A22: DUKE_055 | B22: DUKE | C22: 0 | D22: 0 | F22: 0 | G22: 0 | H22: 1 | I22: 0 | J22: 664 | K22: 0 | M22: 0 | N22: 0 | O22: 0 | P22: 0 | Q22: 0 | U22: triple_negative | V22: 73 | W22: post | X22: hawaian | Y22: 0 | Z22: 54.431 | AB22: normal | AC22: b | AD22: axial | AE22: 1 | AF22: 5 | AG22: 1 | AH22: 3 | AI22: 512 | AJ22: 512 | AK22: 170 | AL22: [0.6445, 0.6445] | AM22: 1 | AN22: DUKE | AO22: GE | AP22: SIGNA HDx | AQ22: 15 | AR22: 705 | AS22: 1410 | AT22: 2.432 | AU22: 5.808 | AV22: [0, 326, 447, 568, 689] | AX22: 1.3.6.1.4.1.14519.5.2.1.19637182322127812713997353423084608824
A23: DUKE_057 | B23: DUKE | C23: 0 | D23: 0 | F23: 0 | G23: 1 | H23: 0 | I23: 1 | J23: 1603 | K23: 0 | M23: 0 | N23: 1 | O23: 1 | P23: 1 | Q23: 1 | T23: high | U23: her2_enriched | V23: 70 | W23: post | X23: african american | Y23: 0 | Z23: 77.110713 | AA23: 1.6510033 | AB23: overweight | AD23: axial | AE23: 1 | AF23: 4 | AG23: 1 | AH23: 1.5 | AI23: 448 | AJ23: 448 | AK23: 112 | AL23: [0.80357140302658, 0.80357140302658] | AM23: 1.5 | AN23: DUKE | AO23: SIEMENS | AP23: Avanto | AQ23: 11 | AR23: 56 | AS23: 148 | AT23: 1.33 | AU23: 4.27 | AV23: [0, 136, 211, 285] | AX23: 1.3.6.1.4.1.14519.5.2.1.87678102268025627030497449879227437755
A24: DUKE_059 | B24: DUKE | C24: 0 | D24: 1 | F24: 0 | G24: 0 | H24: 1 | I24: 0 | J24: 2226 | K24: 0 | M24: 0 | N24: 0 | O24: 0 | P24: 0 | Q24: 0 | T24: intermediate | U24: triple_negative | V24: 51 | W24: pre | X24: caucasian | Y24: 0 | AD24: axial | AE24: 1 | AF24: 4 | AG24: 1 | AH24: 3 | AI24: 512 | AJ24: 512 | AK24: 182 | AL24: [0.6641, 0.6641] | AM24: 1 | AN24: DUKE | AO24: GE | AP24: Signa HDxt | AQ24: 15 | AR24: 666 | AS24: 1332 | AT24: 2.428 | AU24: 5.669 | AV24: [0, 182, 299, 416] | AX24: 1.3.6.1.4.1.14519.5.2.1.154064829117936049483903250937179540958
A25: DUKE_060 | B25: DUKE | C25: 0 | D25: 0 | F25: 0 | G25: 0 | H25: 0 | I25: 0 | J25: 1833 | K25: 1526 | M25: 0 | N25: 0 | O25: 0 | P25: 0 | Q25: 0 | U25: triple_negative | V25: 47 | W25: pre | X25: african american | Y25: 0 | Z25: 73.482 | AB25: overweight | AC25: c | AD25: axial | AE25: 1 | AF25: 5 | AG25: 1 | AH25: 3 | AI25: 512 | AJ25: 512 | AK25: 178 | AL25: [0.6836, 0.6836] | AM25: 1 | AN25: DUKE | AO25: GE | AP25: SIGNA HDx | AQ25: 15 | AR25: 823 | AS25: 1647 | AT25: 2.404 | AU25: 5.517 | AV25: [0, 263, 482, 604, 726] | AX25: 1.3.6.1.4.1.14519.5.2.1.179938739598958943568048593082124063967
A26: DUKE_061 | B26: DUKE | C26: 0 | D26: 1 | F26: 0 | G26: 0 | H26: 1 | I26: 1 | J26: 188 | K26: 0 | M26: 220 | N26: 0 | O26: 0 | P26: 0 | Q26: 0 | T26: high | U26: triple_negative | V26: 59 | W26: post | X26: african american | Y26: 0 | Z26: 71 | AB26: overweight | AD26: axial | AE26: 1 | AF26: 4 | AG26: 1 | AH26: 1.5 | AI26: 512 | AJ26: 512 | AK26: 174 | AL26: [0.6641, 0.6641] | AM26: 1 | AN26: DUKE | AO26: GE | AP26: Optima MR450w | AQ26: 15 | AR26: 475 | AS26: 951 | AT26: 2.516 | AU26: 5.38 | AV26: [0, 268, 385, 502] | AX26: 1.3.6.1.4.1.14519.5.2.1.108872398847262229983257156206321964740
A27: DUKE_064 | B27: DUKE | C27: 0 | D27: 0 | F27: 0 | G27: 0 | H27: 0 | I27: 0 | J27: 2922 | K27: 0 | M27: 0 | N27: 0 | O27: 0 | P27: 0 | Q27: 0 | T27: intermediate | U27: triple_negative | V27: 55 | W27: post | X27: caucasian | Y27: 0 | AD27: axial | AE27: 1 | AF27: 5 | AG27: 1 | AH27: 3 | AI27: 512 | AJ27: 512 | AK27: 162 | AL27: [0.6445, 0.6445] | AM27: 1 | AN27: DUKE | AO27: GE | AP27: SIGNA HDx | AQ27: 15 | AR27: 732 | AS27: 1464 | AT27: 2.444 | AU27: 5.809 | AV27: [0, 208, 402, 536, 665] | AX27: 1.3.6.1.4.1.14519.5.2.1.147955914978633063127428256313532881801
A28: DUKE_069 | B28: DUKE | C28: 0 | D28: 0 | F28: 0 | G28: 0 | H28: 0 | I28: 0 | J28: 701 | K28: 0 | M28: 0 | N28: 1 | O28: 1 | P28: 1 | Q28: 0 | U28: luminal | V28: 46 | W28: pre | X28: caucasian | Y28: 0 | Z28: 58.967 | AB28: normal | AC28: c | AD28: axial | AE28: 1 | AF28: 5 | AG28: 1 | AH28: 1.5 | AI28: 512 | AJ28: 512 | AK28: 196 | AL28: [0.6641, 0.6641] | AM28: 1 | AN28: DUKE | AO28: GE | AP28: SIGNA HDx | AQ28: 15 | AR28: 326 | AS28: 652 | AT28: 2.32 | AU28: 4.936 | AV28: [0, 277, 398, 519, 640] | AX28: 1.3.6.1.4.1.14519.5.2.1.163217082269636582489284908405853808874
A29: DUKE_071 | B29: DUKE | C29: 0 | D29: 1 | F29: 0 | G29: 0 | H29: 0 | I29: 0 | J29: 2052 | K29: 0 | M29: 0 | N29: 1 | O29: 1 | P29: 1 | Q29: 0 | T29: high | U29: luminal | V29: 35 | W29: pre | X29: caucasian | Y29: 0 | Z29: 56.699 | AB29: normal | AD29: axial | AE29: 1 | AF29: 4 | AG29: 1 | AH29: 1.5 | AI29: 512 | AJ29: 512 | AK29: 196 | AL29: [0.6641, 0.6641] | AM29: 1 | AN29: DUKE | AO29: GE | AP29: Signa HDxt | AQ29: 15 | AR29: 295 | AS29: 591 | AT29: 2.32 | AU29: 4.936 | AV29: [0, 922, 1036, 1150] | AX29: 1.3.6.1.4.1.14519.5.2.1.318477618058194737038846033112793175876
A30: DUKE_077 | B30: DUKE | C30: 0 | D30: 0 | F30: 0 | G30: 0 | H30: 0 | I30: 0 | J30: 1702 | K30: 0 | M30: 0 | N30: 0 | O30: 0 | P30: 0 | Q30: 0 | U30: triple_negative | V30: 38 | W30: pre | X30: caucasian | Y30: 0 | Z30: 67.132 | AB30: normal | AD30: axial | AE30: 1 | AF30: 5 | AG30: 1 | AH30: 3 | AI30: 512 | AJ30: 512 | AK30: 174 | AL30: [0.6836, 0.6836] | AM30: 1 | AN30: DUKE | AO30: GE | AP30: SIGNA HDx | AQ30: 15 | AR30: 1016 | AS30: 2033 | AT30: 2.4 | AU30: 5.519 | AV30: [0, 139, 351, 467, 583] | AX30: 1.3.6.1.4.1.14519.5.2.1.164065338920500492667606880117873369290
A31: DUKE_082 | B31: DUKE | C31: 0 | D31: 1 | F31: 0 | G31: 0 | H31: 0 | I31: 0 | J31: 575 | K31: 0 | M31: 0 | N31: 1 | O31: 1 | P31: 1 | Q31: 0 | T31: intermediate | U31: luminal | V31: 29 | W31: pre | X31: asian | Y31: 0 | Z31: 62.595755 | AA31: 1.6002032 | AB31: normal | AD31: axial | AE31: 1 | AF31: 4 | AG31: 1 | AH31: 1.5 | AI31: 448 | AJ31: 448 | AK31: 176 | AL31: [0.75892859697342, 0.75892859697342] | AM31: 1.1 | AN31: DUKE | AO31: SIEMENS | AP31: Avanto | AQ31: 11 | AR31: 60 | AS31: 155 | AT31: 1.36 | AU31: 4.31 | AV31: [0, 189, 316, 442] | AX31: 1.3.6.1.4.1.14519.5.2.1.203505445198377129570893210428900718180
A32: DUKE_086 | B32: DUKE | C32: 0 | D32: 1 | F32: 0 | G32: 1 | H32: 0 | I32: 1 | J32: 888 | K32: 0 | M32: 0 | N32: 1 | O32: 1 | P32: 1 | Q32: 1 | T32: intermediate | U32: her2_enriched | V32: 36 | W32: pre | X32: caucasian | Y32: 0 | Z32: 68.492457 | AA32: 1.6256033 | AB32: overweight | AD32: axial | AE32: 1 | AF32: 4 | AG32: 1 | AH32: 3 | AI32: 448 | AJ32: 448 | AK32: 208 | AL32: [0.78125, 0.78125] | AM32: 1 | AN32: DUKE | AO32: SIEMENS | AP32: Skyra | AQ32: 11 | AR32: 33 | AS32: 88 | AT32: 1.44 | AU32: 3.77 | AV32: [0, 226, 326, 426] | AX32: 1.3.6.1.4.1.14519.5.2.1.238735150432802860027977259854459327592
A33: DUKE_090 | B33: DUKE | C33: 0 | D33: 0 | F33: 0 | G33: 1 | H33: 0 | I33: 0 | J33: 199 | K33: 0 | M33: 0 | N33: 0 | O33: 0 | P33: 0 | Q33: 1 | T33: high | U33: her2_pure | V33: 60 | W33: post | X33: caucasian | Y33: 0 | Z33: 61.689 | AB33: normal | AD33: axial | AE33: 1 | AF33: 4 | AG33: 1 | AH33: 3 | AI33: 512 | AJ33: 512 | AK33: 196 | AL33: [0.6836, 0.6836] | AM33: 1 | AN33: DUKE | AO33: GE | AP33: Signa HDxt | AQ33: 15 | AR33: 395 | AS33: 791 | AT33: 2.396 | AU33: 5.516 | AV33: [0, 154, 274, 395] | AX33: 1.3.6.1.4.1.14519.5.2.1.194651386297649379035931320896715949363
A34: DUKE_091 | B34: DUKE | C34: 0 | D34: 0 | F34: 0 | G34: 0 | H34: 0 | I34: 1 | J34: 1984 | K34: 0 | M34: 0 | N34: 1 | O34: 1 | P34: 1 | Q34: 0 | U34: luminal | V34: 65 | W34: post | X34: african american | Y34: 0 | Z34: 77.110713 | AB34: overweight | AC34: b | AD34: axial | AE34: 1 | AF34: 5 | AG34: 1 | AH34: 1.5 | AI34: 448 | AJ34: 448 | AK34: 160 | AL34: [0.75892859697342, 0.75892859697342] | AM34: 1.1 | AN34: DUKE | AO34: SIEMENS | AP34: Avanto | AQ34: 11 | AR34: 50 | AS34: 134 | AT34: 1.39 | AU34: 4.12 | AV34: [0, 621, 745, 868, 993] | AX34: 1.3.6.1.4.1.14519.5.2.1.275257635870315432477619402942964187802
A35: DUKE_097 | B35: DUKE | C35: 0 | D35: 0 | F35: 0 | G35: 0 | H35: 0 | I35: 0 | J35: 1088 | K35: 0 | M35: 0 | N35: 0 | O35: 0 | P35: 0 | Q35: 0 | T35: high | U35: triple_negative | V35: 56 | W35: pre | X35: caucasian | Y35: 0 | AD35: axial | AE35: 1 | AF35: 4 | AG35: 1 | AH35: 3 | AI35: 448 | AJ35: 448 | AK35: 208 | AL35: [0.78125, 0.78125] | AM35: 1 | AN35: DUKE | AO35: SIEMENS | AP35: Skyra | AQ35: 15 | AR35: 61 | AS35: 168 | AT35: 1.44 | AU35: 3.77 | AV35: [0, 212, 311, 411] | AX35: 1.3.6.1.4.1.14519.5.2.1.129967585192783878980707247369022773138
A36: DUKE_099 | B36: DUKE | C36: 0 | D36: 1 | F36: 0 | G36: 0 | H36: 1 | I36: 1 | J36: 1416 | K36: 0 | M36: 0 | N36: 0 | O36: 0 | P36: 0 | Q36: 0 | U36: triple_negative | V36: 69 | W36: post | X36: caucasian | Y36: 0 | Z36: 74.843 | AB36: overweight | AD36: axial | AE36: 1 | AF36: 5 | AG36: 1 | AH36: 3 | AI36: 512 | AJ36: 512 | AK36: 148 | AL36: [0.625, 0.625] | AM36: 1 | AN36: DUKE | AO36: GE | AP36: SIGNA HDx | AQ36: 15 | AR36: 663 | AS36: 1326 | AT36: 2.464 | AU36: 5.987 | AV36: [0, 173, 278, 383, 488] | AX36: 1.3.6.1.4.1.14519.5.2.1.186695500940488501618389117544955236837
A37: DUKE_101 | B37: DUKE | C37: 0 | D37: 1 | F37: 0 | G37: 0 | H37: 0 | I37: 1 | J37: 1609 | K37: 0 | M37: 0 | N37: 1 | O37: 1 | P37: 1 | Q37: 0 | U37: luminal | V37: 45 | W37: post | X37: caucasian | Y37: 0 | Z37: 75.296343 | AB37: overweight | AD37: axial | AE37: 1 | AF37: 5 | AG37: 1 | AH37: 3 | AI37: 448 | AJ37: 448 | AK37: 160 | AL37: [0.69196426868439, 0.69196426868439] | AM37: 1.1 | AN37: DUKE | AO37: SIEMENS | AP37: TrioTim | AQ37: 11 | AR37: 65 | AS37: 177 | AT37: 1.49 | AU37: 4.09 | AV37: [0, 214, 349, 479, 610] | AX37: 1.3.6.1.4.1.14519.5.2.1.68763652285344731591907514089625240751
A38: DUKE_103 | B38: DUKE | C38: 0 | D38: 1 | F38: 0 | G38: 1 | H38: 0 | I38: 0 | J38: 1082 | K38: 0 | M38: 0 | N38: 1 | O38: 1 | P38: 1 | Q38: 1 | T38: intermediate | U38: her2_enriched | V38: 51 | W38: pre | X38: caucasian | Y38: 0 | Z38: 51.709537 | AA38: 1.6256033 | AB38: normal | AD38: axial | AE38: 1 | AF38: 3 | AG38: 1 | AH38: 1.5 | AI38: 448 | AJ38: 448 | AK38: 144 | AL38: [0.75892859697342, 0.75892859697342] | AM38: 1.0999999 | AN38: DUKE | AO38: SIEMENS | AP38: Avanto | AQ38: 11 | AR38: 63 | AS38: 161 | AT38: 1.36 | AU38: 4.31 | AV38: [0, 157, 254] | AX38: 1.3.6.1.4.1.14519.5.2.1.322399265116643135620910336253787514497
A39: DUKE_104 | B39: DUKE | C39: 0 | D39: 0 | F39: 0 | G39: 0 | H39: 0 | I39: 0 | J39: 1671 | K39: 0 | M39: 0 | N39: 1 | O39: 1 | P39: 1 | Q39: 0 | T39: intermediate | U39: luminal | V39: 71 | W39: post | X39: african american | Y39: 0 | Z39: 85.728969 | AA39: 1.7272035 | AB39: overweight | AD39: axial | AE39: 1 | AF39: 4 | AG39: 1 | AH39: 1.5 | AI39: 448 | AJ39: 448 | AK39: 176 | AL39: [0.80357140302658, 0.80357140302658] | AM39: 1 | AN39: DUKE | AO39: SIEMENS | AP39: Avanto | AQ39: 11 | AR39: 120 | AS39: 336 | AT39: 1.33 | AU39: 4.31 | AV39: [0, 211, 331, 449] | AX39: 1.3.6.1.4.1.14519.5.2.1.224701010678361534685145255527557683258
A40: DUKE_105 | B40: DUKE | C40: 0 | D40: 0 | F40: 0 | G40: 1 | H40: 1 | I40: 0 | J40: 1406 | K40: 0 | M40: 0 | N40: 0 | O40: 0 | P40: 0 | Q40: 1 | U40: her2_pure | V40: 29 | W40: pre | X40: caucasian | Y40: 0 | Z40: 54.431 | AB40: normal | AC40: d | AD40: axial | AE40: 1 | AF40: 5 | AG40: 1 | AH40: 3 | AI40: 512 | AJ40: 512 | AK40: 156 | AL40: [0.6445, 0.6445] | AM40: 1 | AN40: DUKE | AO40: GE | AP40: SIGNA HDx | AQ40: 15 | AR40: 642 | AS40: 1284 | AT40: 2.432 | AU40: 5.814 | AV40: [0, 249, 357, 465, 573] | AX40: 1.3.6.1.4.1.14519.5.2.1.163656381399884188057039150101799337730
...

Sheet analysis
B1: Unilateral/Unifocal | C1: Multifocal | D1: Bilateral
A2: Num Patients | B2: =1506 - SUM(C2:D2) -> 937 | C2: =SUM(dataset_info!D:D) -> 539 | D2: =SUM(dataset_info!C:C) -> 30 | E2: =SUM(B2:D2) -> 1506
B4: Unlabeled | C4: Pre-menopause | D4: Post-menopause
A5: Num Patients | B5: =COUNTBLANK(dataset_info!W2:W1507) -> 408 | C5: {=SUMPRODUCT(--(ISNUMBER(SEARCH("pre", dataset_info!W:W)) + ISNUMBER(SEARCH("peri", dataset_info!W:W)) > 0))} -> 678 | D5: {=SUMPRODUCT(--ISNUMBER(SEARCH("post", dataset_info!W2:W1507)))} -> 420 | E5: =SUM(C5:D5) -> 1098
B7: Unlabeled | C7: A | D7: B | E7: C | F7: D
A8: Num Patients | B8: =COUNTBLANK(dataset_info!AC2:AC1507) -> 1446 | C8: {=SUMPRODUCT(--ISNUMBER(SEARCH("a", dataset_info!AC2:AC1507)))} -> 3 | D8: {=SUMPRODUCT(--ISNUMBER(SEARCH("b", dataset_info!AC2:AC1507)))} -> 14 | E8: {=SUMPRODUCT(--ISNUMBER(SEARCH("c", dataset_info!AC2:AC1507)))} -> 31 | F8: {=SUMPRODUCT(--ISNUMBER(SEARCH("d", dataset_info!AC2:AC1507)))} -> 12 | G8: =SUM(C8:F8) -> 60 | H8: =B8/G8 -> 24.1
B10: 3 | C10: 4 | D10: 5 | E10: 6
A11: Num Patients | B11: =COUNTIF(dataset_info!$AF:$AF, "=3") -> 205 | C11: =COUNTIF(dataset_info!$AF:$AF, "=4") -> 179 | D11: =COUNTIF(dataset_info!$AF:$AF, "=5") -> 137 | E11: =COUNTIF(dataset_info!$AF:$AF, "=6") -> 985 | F11: =SUM(B11:E11) -> 1506

Sheet legend
A1: Field | B1: Description | C1: Options | D1: Unnamed: 3
A2: patient_id | B2: Dataset and identfication number (ID) of the patient | C2: The ID number of the source dataset is kept
A3: dataset | B3: Name of the source dataset from TCIA | C3: DUKE
C4: ISPY1
C5: ISPY2
C6: NACT
A7: bilateral_breast_cancer | B7: The patient has bilateral breast cancer | C7: 0: no, 1: yes, empty: no info available
A8: multifocal cancer | B8: The patient has two or more distinct tumor masses in the same breast | C8: 0: no, 1: yes, empty: no info available
A9: nac_agent | B9: Treatment agent | C9: Anthracycline
C10: Taxane
C11: Paclitaxel
C12: FEC100
C13: T-DM1
C14: Pertuzumab
C15: Trastuzumab
C16: Ganitumab
C17: Ganetespib
C18: Neratinib
C19: AMG 386
C20: ABT 888
C21: MK-2206
C22: Carboplatin
A23: endocrine_therapy | B23: The patient received endocrine therapy | C23: 0: no, 1: yes, empty: no info available
A24: anti_her2_neu_therapy | B24: The patient received anti _HER2 neu therapy | C24: 0: no, 1: yes, empty: no info available
A25: pcr | B25: Pathological complete response to neoadjuvant chemotherapy | C25: 0: no, 1: yes, empty: no info available
A26: mastectomy_post_nac | B26: Mastectomy surgery after nac treatment | C26: 0: no, 1: yes, empty: no info available
A27: days_to_follow_up | B27: Number of days until the last follow up or death | C27: days, if empty no ifo is available
A28: days_to_recurrence | B28: Number of days until tumor recurrence | C28: 0: no recurrence
C29: >0: days to recurrence
C30: empty: no info available
A31: days_to_death | B31: Number of days until death | C31: 0: no death
C32: >0: days to death
C33: empty: no info available
A34: days_to_metastasis | B34: Number of days until tumor recurrence with metastasis | C34: 0: no metastasis
C35: >0: days to metastasis
C36: empty: no info available
A37: hr | B37: Hormone Receptor | C37: 0: negative, 1: positive, empty: no info available
A38: er | B38: Estrogen Receptor | C38: 0: negative, 1: positive, empty: no info available
A39: pr | B39: Progesterone Receptor | C39: 0: negative, 1: positive, empty: no info available
A40: her2 | B40: Human Epidermal growth factor Receptor 2 | C40: 0: negative, 1: positive, empty: no info available
...
